[[!comment format=mdwn
 username="Atemu"
 avatar="http://cdn.libravatar.org/avatar/d1f0f4275931c552403f4c6707bead7a"
 subject="comment 2"
 date="2022-08-07T08:05:23Z"
 content="""
Thanks for looking into this!

> However, I have not been able to reproduce it so far. I tried making 8 different files each 100 mb, and was able to copy them all to a bup repository concurrently with no failures.

You need more than that; 8 Files might randomly work without error.

Perhaps it only really manifests itself on smaller files? That's mainly what I've been copying.

Here's an example output of git-annex 6d762fafae45cb1f6a6106ac25f347631d6d0ca8 `git-annex copy --not --in bup --to bup -J2 --all`:

```
...
copy SHA256E-s227509--23bcff8394a16cb8ae090ac9f67e7cccb8a2c4354788b11426bfc14d01c136c6.csv (to bup...) 
  bup [\"split\",\"-r\",\"/tmp/bup\",\"-q\",\"-n\",\"SHA256E-s227509--23bcff8394a16cb8ae090ac9f67e7cccb8a2c4354788b11426bfc14d01c136c6.csv\"] exited 1 (stderr output: Traceback (most recent call last):
    File \"/nix/store/xqgy6d53wbazvkjcgqwdpbww4s87b69z-bup-0.32/lib/bup/cmd/bup-midx\", line 298, in <module>
      do_midx_dir(path, opt.output, byte_stream(sys.stdout))
    File \"/nix/store/xqgy6d53wbazvkjcgqwdpbww4s87b69z-bup-0.32/lib/bup/cmd/bup-midx\", line 192, in do_midx_dir
      m = git.open_idx(mname)
    File \"/nix/store/xqgy6d53wbazvkjcgqwdpbww4s87b69z-bup-0.32/lib/bup/cmd/../bup/git.py\", line 668, in open_idx
      return midx.PackMidx(filename)
    File \"/nix/store/xqgy6d53wbazvkjcgqwdpbww4s87b69z-bup-0.32/lib/bup/cmd/../bup/midx.py\", line 29, in __init__
      self.map = mmap_read(open(filename))
  FileNotFoundError: [Errno 2] No such file or directory: b'/tmp/bup/index-cache/None__tmp_bup/midx-5bfad00d8c17012ca48231b22dd894649c385b15.midx'
  [b'/nix/store/xqgy6d53wbazvkjcgqwdpbww4s87b69z-bup-0.32/lib/bup/cmd/bup', b'midx', b'--auto', b'--dir', b'/tmp/bup/index-cache/None__tmp_bup']: returned 1
  WARNING: 1 errors encountered while saving.
  )
ok
copy SHA256E-s6061--b57b1e42ee05102f095d700c9bcb12b48142a9c57879573d3fd128d181b60f5f.txt.user (to bup...) ok
copy SHA256E-s1861--86988a46008289c58943f2e59f4e543fdec3fc9853ce8b53375e11f9ccbd4138.cpp (to bup...) 
  bup [\"split\",\"-r\",\"/tmp/bup\",\"-q\",\"-n\",\"SHA256E-s1861--86988a46008289c58943f2e59f4e543fdec3fc9853ce8b53375e11f9ccbd4138.cpp\"] exited 1 (stderr output: Traceback (most recent call last):
    File \"/nix/store/xqgy6d53wbazvkjcgqwdpbww4s87b69z-bup-0.32/lib/bup/cmd/bup-server\", line 320, in <module>
      cmd(conn, rest)
    File \"/nix/store/xqgy6d53wbazvkjcgqwdpbww4s87b69z-bup-0.32/lib/bup/cmd/bup-server\", line 137, in receive_objects_v2
      oldpack = w.exists(shar, want_source=True)
    File \"/nix/store/xqgy6d53wbazvkjcgqwdpbww4s87b69z-bup-0.32/lib/bup/cmd/../bup/git.py\", line 804, in exists
      self._require_objcache()
    File \"/nix/store/xqgy6d53wbazvkjcgqwdpbww4s87b69z-bup-0.32/lib/bup/cmd/../bup/git.py\", line 797, in _require_objcache
      self.objcache = self.objcache_maker()
    File \"/nix/store/xqgy6d53wbazvkjcgqwdpbww4s87b69z-bup-0.32/lib/bup/cmd/../bup/git.py\", line 686, in _make_objcache
      return PackIdxList(repo(b'objects/pack'))
    File \"/nix/store/xqgy6d53wbazvkjcgqwdpbww4s87b69z-bup-0.32/lib/bup/cmd/../bup/git.py\", line 517, in __init__
      self.refresh()
    File \"/nix/store/xqgy6d53wbazvkjcgqwdpbww4s87b69z-bup-0.32/lib/bup/cmd/../bup/git.py\", line 607, in refresh
      midxl.sort(key=lambda ix:
    File \"/nix/store/xqgy6d53wbazvkjcgqwdpbww4s87b69z-bup-0.32/lib/bup/cmd/../bup/git.py\", line 608, in <lambda>
      (-len(ix), -xstat.stat(ix.name).st_mtime))
    File \"/nix/store/xqgy6d53wbazvkjcgqwdpbww4s87b69z-bup-0.32/lib/bup/cmd/../bup/xstat.py\", line 131, in stat
      return stat_result.from_xstat_rep(_helpers.stat(path))
  FileNotFoundError: [Errno 2] No such file or directory: '/tmp/bup/objects/pack/midx-13188bb9c81006e5bc683627ee9fe186c09a9104.midx'
  Traceback (most recent call last):
    File \"/nix/store/xqgy6d53wbazvkjcgqwdpbww4s87b69z-bup-0.32/lib/bup/cmd/bup-split\", line 232, in <module>
      pack_writer.close()  # must close before we can update the ref
    File \"/nix/store/xqgy6d53wbazvkjcgqwdpbww4s87b69z-bup-0.32/lib/bup/cmd/../bup/client.py\", line 520, in close
      id = self._end()
    File \"/nix/store/xqgy6d53wbazvkjcgqwdpbww4s87b69z-bup-0.32/lib/bup/cmd/../bup/client.py\", line 517, in _end
      return self.suggest_packs() # Returns last idx received
    File \"/nix/store/xqgy6d53wbazvkjcgqwdpbww4s87b69z-bup-0.32/lib/bup/cmd/../bup/client.py\", line 285, in _suggest_packs
      self.check_ok()
    File \"/nix/store/xqgy6d53wbazvkjcgqwdpbww4s87b69z-bup-0.32/lib/bup/cmd/../bup/client.py\", line 155, in check_ok
      raise ClientError('server exited unexpectedly with code %r'
  bup.client.ClientError: server exited unexpectedly with code 1
  )
ok
copy SHA256E-s247--598ca11afb6b5a92fb0539d5e51b5933986a02b9af76c306ed0e3d123eba7f73.org (to bup...) ok
copy SHA256E-s17120--e883a44474fb01cb2598a35de65bb8f149e8a86f0edad9e769c29cb47738f1d7.org (to bup...) ok
copy SHA256E-s51256--6a45e5a834b84467ca8730b19d11997b1fda618e8264f3052466b0c0d9df33fb (to bup...) ok
copy SHA256E-s138590--273323cbd322923f9d19280b6b4fa73bfa3638d2982b685b9efcaee43c988a07.pdf (to bup...) ok
copy SHA256E-s1142--68e432e17b706adc8fed0c6e573957ebf3fdb3c2ed52152e8e11ff68742a964c.cpp (to bup...) ok
copy SHA256E-s2357--88f5bd074dce62a99f67a2fcb89f69edc323f5b781c43f75e2266caa75f452a8.nix (to bup...) ok
copy SHA256E-s17167--f1a52bf34dc0c09bd05ea76c129bca1edf01cb1634967facddc87ceed030ac0e.org (to bup...) ok
copy SHA256E-s20152--ec24a0a718ff33a20fd18a672e7f8e8d29358a4930a0cb668fc023c6319acff2.cpp (to bup...) ok
copy SHA256E-s74935712--48a36e91a03d46fe73ec361454b9cd3808ae0a6d5372df089c2400ea135269e1.pptx (to bup...) ok
copy SHA256E-s32801--33568e97fb3c67d5646698a3157d2387ccbd447dbe846604e21f135962b7a82a.org (to bup...) ok
copy SHA256E-s1112--08efad2257400abb2a011b7a2bcee115ad69a7c5f8fe622df94f9252e767f4b1.cpp (to bup...) ok
copy SHA256E-s4--af489f7170eaf213b960628333c4752e3907304303ed0b052b43d864d2653c2e (to bup...) ok
copy SHA256E-s270--fd3d6db55c73971d25b7a12211f618ee0f5b9185329974e15a71b8c7313b71d3.org (to bup...) ok
copy SHA256E-s26781--66ff44f139d2f825d6202437078e2a6652214f2d4841f618268a39cb25919c52.org (to bup...) ok
copy SHA256E-s267--5face6a2e6cf04634542c17626cfb273b5cd6d1ff8cad644bb3dfd50b5b26c10 (to bup...) ok
copy SHA256E-s1117802--d9b03b85205196237df6bdcaaa74642db77da46fbea35d1e0de4034f24387cf4.pdf (to bup...) ok
copy SHA256E-s265--fc2aec4bcb3af72e043a2f892440a1370ed19704cf4fb4a3cc26114441b6f8d0.org (to bup...) ok
copy SHA256E-s34783--ad8860a118f942f58672a95c2df3dcfbfd2cc8ee3f5930f52bfbb88dc0a90132.org (to bup...) ok
copy SHA256E-s56184--30106a0f9dd300f8a88e2eb88b2a184a1342874afa2cb4aaa64404a187f1e8c4 (to bup...) ok
copy SHA256E-s74919040--86dcfa59caa040dcfc512bc41b8fe652abc0814324f8fe18d88043a14ecf4402.pptx (to bup...) ok
copy SHA256E-s26013--0bae4beaba4bdf971bd79061a215e2835953b3bb00e532fb0341e6628b796008.org (to bup...) ok
copy SHA256E-s58752--e03f8dc86ed2dc218612022331323a2f5cac319a250b4a24fc15d7312ee9e607 (to bup...) ok
copy SHA256E-s8847--cc7aa3b84e82f7aa197d653f41b545a1e807c98f16187210ded3d2463b41ea86.csv (to bup...) ok
copy SHA256E-s21189--8ffdc40240a69693c596b70a94dd58258cd753b41f34e0c16c38d8dbd89f698e.org (to bup...) ok
copy SHA256E-s24137--9a5c833a7f70f53ba26aa26e3dd2faf22b16e1c4ce33c5733d0a2109560b7c71.org (to bup...) ok
copy SHA256E-s359450--0d0ec93306f455d231ede0e8f2f6c047dd94e0de9a16639e1a7f0b3d86203ac3.pdf (to bup...) 
  bup [\"split\",\"-r\",\"/tmp/bup\",\"-q\",\"-n\",\"SHA256E-s359450--0d0ec93306f455d231ede0e8f2f6c047dd94e0de9a16639e1a7f0b3d86203ac3.pdf\"] exited 1 (stderr output: Traceback (most recent call last):
    File \"/nix/store/xqgy6d53wbazvkjcgqwdpbww4s87b69z-bup-0.32/lib/bup/cmd/bup-midx\", line 298, in <module>
      do_midx_dir(path, opt.output, byte_stream(sys.stdout))
    File \"/nix/store/xqgy6d53wbazvkjcgqwdpbww4s87b69z-bup-0.32/lib/bup/cmd/bup-midx\", line 198, in do_midx_dir
      midxs.sort(key=lambda ix: (-sizes[ix], -xstat.stat(ix).st_mtime))
    File \"/nix/store/xqgy6d53wbazvkjcgqwdpbww4s87b69z-bup-0.32/lib/bup/cmd/bup-midx\", line 198, in <lambda>
      midxs.sort(key=lambda ix: (-sizes[ix], -xstat.stat(ix).st_mtime))
    File \"/nix/store/xqgy6d53wbazvkjcgqwdpbww4s87b69z-bup-0.32/lib/bup/cmd/../bup/xstat.py\", line 131, in stat
      return stat_result.from_xstat_rep(_helpers.stat(path))
  FileNotFoundError: [Errno 2] No such file or directory: '/tmp/bup/index-cache/None__tmp_bup/midx-3da3384b3acf53204d7890e1bc78030c8b46b3a9.midx'
  [b'/nix/store/xqgy6d53wbazvkjcgqwdpbww4s87b69z-bup-0.32/lib/bup/cmd/bup', b'midx', b'--auto', b'--dir', b'/tmp/bup/index-cache/None__tmp_bup']: returned 1
  WARNING: 1 errors encountered while saving.
  )
ok
copy SHA256E-s1433--20e8793d98da9272424818b56c28af028c1568ec3e82967d6f07ff81015c4108.cpp (to bup...) ok
copy SHA256E-s91176--46ebe34cba131ea6ced189768edccfbf7eb4b7e33fa0be53c36c7888e2bff4a5 (to bup...) 
  bup [\"split\",\"-r\",\"/tmp/bup\",\"-q\",\"-n\",\"SHA256E-s91176--46ebe34cba131ea6ced189768edccfbf7eb4b7e33fa0be53c36c7888e2bff4a5\"] exited 1 (stderr output: Traceback (most recent call last):
    File \"/nix/store/xqgy6d53wbazvkjcgqwdpbww4s87b69z-bup-0.32/lib/bup/cmd/bup-server\", line 320, in <module>
      cmd(conn, rest)
    File \"/nix/store/xqgy6d53wbazvkjcgqwdpbww4s87b69z-bup-0.32/lib/bup/cmd/bup-server\", line 137, in receive_objects_v2
      oldpack = w.exists(shar, want_source=True)
    File \"/nix/store/xqgy6d53wbazvkjcgqwdpbww4s87b69z-bup-0.32/lib/bup/cmd/../bup/git.py\", line 804, in exists
      self._require_objcache()
    File \"/nix/store/xqgy6d53wbazvkjcgqwdpbww4s87b69z-bup-0.32/lib/bup/cmd/../bup/git.py\", line 797, in _require_objcache
      self.objcache = self.objcache_maker()
    File \"/nix/store/xqgy6d53wbazvkjcgqwdpbww4s87b69z-bup-0.32/lib/bup/cmd/../bup/git.py\", line 686, in _make_objcache
      return PackIdxList(repo(b'objects/pack'))
    File \"/nix/store/xqgy6d53wbazvkjcgqwdpbww4s87b69z-bup-0.32/lib/bup/cmd/../bup/git.py\", line 517, in __init__
      self.refresh()
    File \"/nix/store/xqgy6d53wbazvkjcgqwdpbww4s87b69z-bup-0.32/lib/bup/cmd/../bup/git.py\", line 607, in refresh
      midxl.sort(key=lambda ix:
    File \"/nix/store/xqgy6d53wbazvkjcgqwdpbww4s87b69z-bup-0.32/lib/bup/cmd/../bup/git.py\", line 608, in <lambda>
      (-len(ix), -xstat.stat(ix.name).st_mtime))
    File \"/nix/store/xqgy6d53wbazvkjcgqwdpbww4s87b69z-bup-0.32/lib/bup/cmd/../bup/xstat.py\", line 131, in stat
      return stat_result.from_xstat_rep(_helpers.stat(path))
  FileNotFoundError: [Errno 2] No such file or directory: '/tmp/bup/objects/pack/midx-4b7dfbb64132c6a9e65912f5d75a49fcc27dfc14.midx'
  Traceback (most recent call last):
    File \"/nix/store/xqgy6d53wbazvkjcgqwdpbww4s87b69z-bup-0.32/lib/bup/cmd/bup-split\", line 232, in <module>
      pack_writer.close()  # must close before we can update the ref
    File \"/nix/store/xqgy6d53wbazvkjcgqwdpbww4s87b69z-bup-0.32/lib/bup/cmd/../bup/client.py\", line 520, in close
      id = self._end()
    File \"/nix/store/xqgy6d53wbazvkjcgqwdpbww4s87b69z-bup-0.32/lib/bup/cmd/../bup/client.py\", line 517, in _end
      return self.suggest_packs() # Returns last idx received
    File \"/nix/store/xqgy6d53wbazvkjcgqwdpbww4s87b69z-bup-0.32/lib/bup/cmd/../bup/client.py\", line 285, in _suggest_packs
      self.check_ok()
    File \"/nix/store/xqgy6d53wbazvkjcgqwdpbww4s87b69z-bup-0.32/lib/bup/cmd/../bup/client.py\", line 155, in check_ok
      raise ClientError('server exited unexpectedly with code %r'
  bup.client.ClientError: server exited unexpectedly with code 1
  )
ok
copy SHA256E-s84648--95ced533e6e0117e09eb0c6e887e3258ccd85e7c14b376a48683028d1959e6f4 (to bup...) ok
copy SHA256E-s33116--1c7622be0217bef8b345d7a2d741a1ea7140df79fb69ee966d0e2596aedd9b92.org (to bup...) ok
copy SHA256E-s1405--707992e818ada3dcf8ddee86d0bf01db6206e1cd9354c8b32bd760a842757890.cpp (to bup...) ok
copy SHA256E-s34172--5ae202572227ab6df161298ab61c4bfe5ebca4b710e8646602c910996c9c4229.org (to bup...) ok
copy SHA256E-s1406289--7462f1e3ca02e796090fe2ba18a50168a24f5cabc66bb8bf949836d4c81774cb.csv (to bup...) ok
copy SHA256E-s263520--1ae605c38fb827de59f90fe304ad20c673a2d8fcbf8166a4cf44bfc45320fb43 (to bup...) ok
copy SHA256E-s57968--830ff82c9c697a29a7cdf1f4765aadb532e42c932a01c45eafe3d66b254dc30b (to bup...) ok
copy SHA256E-s16350--45d12a82d07c62c00fbb211b3cfbc7abea2fb8b4b1777140b56ebee9244ef7af.org (to bup...) 
  bup [\"split\",\"-r\",\"/tmp/bup\",\"-q\",\"-n\",\"SHA256E-s16350--45d12a82d07c62c00fbb211b3cfbc7abea2fb8b4b1777140b56ebee9244ef7af.org\"] exited 1 (stderr output: Traceback (most recent call last):
    File \"/nix/store/xqgy6d53wbazvkjcgqwdpbww4s87b69z-bup-0.32/lib/bup/cmd/bup-midx\", line 298, in <module>
      do_midx_dir(path, opt.output, byte_stream(sys.stdout))
    File \"/nix/store/xqgy6d53wbazvkjcgqwdpbww4s87b69z-bup-0.32/lib/bup/cmd/bup-midx\", line 198, in do_midx_dir
      midxs.sort(key=lambda ix: (-sizes[ix], -xstat.stat(ix).st_mtime))
    File \"/nix/store/xqgy6d53wbazvkjcgqwdpbww4s87b69z-bup-0.32/lib/bup/cmd/bup-midx\", line 198, in <lambda>
      midxs.sort(key=lambda ix: (-sizes[ix], -xstat.stat(ix).st_mtime))
    File \"/nix/store/xqgy6d53wbazvkjcgqwdpbww4s87b69z-bup-0.32/lib/bup/cmd/../bup/xstat.py\", line 131, in stat
      return stat_result.from_xstat_rep(_helpers.stat(path))
  FileNotFoundError: [Errno 2] No such file or directory: '/tmp/bup/index-cache/None__tmp_bup/midx-fef6f07a351680cef8630a1c0ba203f2ed8c0e72.midx'
  [b'/nix/store/xqgy6d53wbazvkjcgqwdpbww4s87b69z-bup-0.32/lib/bup/cmd/bup', b'midx', b'--auto', b'--dir', b'/tmp/bup/index-cache/None__tmp_bup']: returned 1
  WARNING: 1 errors encountered while saving.
  )
ok
copy SHA256E-s2--9a271f2a916b0b6ee6cecb2426f0b3206ef074578be55d9bc94f6f3fe3ab86aa (to bup...) 
  bup [\"split\",\"-r\",\"/tmp/bup\",\"-q\",\"-n\",\"SHA256E-s2--9a271f2a916b0b6ee6cecb2426f0b3206ef074578be55d9bc94f6f3fe3ab86aa\"] exited 1 (stderr output: Traceback (most recent call last):
    File \"/nix/store/xqgy6d53wbazvkjcgqwdpbww4s87b69z-bup-0.32/lib/bup/cmd/bup-midx\", line 298, in <module>
      do_midx_dir(path, opt.output, byte_stream(sys.stdout))
    File \"/nix/store/xqgy6d53wbazvkjcgqwdpbww4s87b69z-bup-0.32/lib/bup/cmd/bup-midx\", line 198, in do_midx_dir
      midxs.sort(key=lambda ix: (-sizes[ix], -xstat.stat(ix).st_mtime))
    File \"/nix/store/xqgy6d53wbazvkjcgqwdpbww4s87b69z-bup-0.32/lib/bup/cmd/bup-midx\", line 198, in <lambda>
      midxs.sort(key=lambda ix: (-sizes[ix], -xstat.stat(ix).st_mtime))
    File \"/nix/store/xqgy6d53wbazvkjcgqwdpbww4s87b69z-bup-0.32/lib/bup/cmd/../bup/xstat.py\", line 131, in stat
      return stat_result.from_xstat_rep(_helpers.stat(path))
  FileNotFoundError: [Errno 2] No such file or directory: '/tmp/bup/index-cache/None__tmp_bup/midx-fef6f07a351680cef8630a1c0ba203f2ed8c0e72.midx'
  [b'/nix/store/xqgy6d53wbazvkjcgqwdpbww4s87b69z-bup-0.32/lib/bup/cmd/bup', b'midx', b'--auto', b'--dir', b'/tmp/bup/index-cache/None__tmp_bup']: returned 1
  WARNING: 1 errors encountered while saving.
  )
ok
^C
```

(Ran this on aarch64-darwin because that's all I have access to ATM but x86_64-linux will probably have the same errors.)

Given the error, it indeed looks like a concurrency issue in `bup` itself. Version is 0.32 which is the newest.

"""]]
